<?xml version="1.0"?>
<robot xmlns:xacro="http://ros.org/wiki/xacro">

  <!--
  Author: Cristian Beltran
-->

  <xacro:macro name="robotiq_hande_gripper" params="prefix parent *origin">

    <xacro:include filename="$(find aist_robotiq
			     )/urdf/robotiq_arg2f_transmission.xacro"/>
    <xacro:robotiq_arg2f_transmission prefix="${prefix}"/>

    <joint name="${prefix}base_joint" type="fixed">
      <parent link="${parent}"/>
      <child link="${prefix}base_link"/>
      <xacro:insert_block name="origin"/>
    </joint>
    <link name="${prefix}base_link"/>

    <joint name="${prefix}hande_joint" type="fixed">
      <parent link="${prefix}base_link"/>
      <child link="${prefix}hande_link"/>
      <origin xyz="0 0 0" rpy="${pi/2} 0 ${pi/2}"/>
    </joint>

    <link name="${prefix}hande_link">
      <inertial>
        <origin rpy="0 0 0" xyz="0 0 0.04607"/>
        <mass value="0.86387"/>
        <inertia ixx="1017560E-9" ixy="0" ixz="2235E-9" iyy="1028041E-9" iyz="0" izz="489810E-9"/>
      </inertial>
      <visual>
        <origin rpy="0 0 0" xyz="0 0 0"/>
        <geometry>
          <mesh filename="package://aist_robotiq/meshes/visual/robotiq_hande.dae" scale="1.0 1.0 1.0"/>
        </geometry>
        <material name="Dark">
          <color rgba=".1 0.1 0.1 1.0"/>
        </material>
      </visual>
      <collision>
        <origin rpy="0 0 0" xyz="0 0 0"/>
        <geometry>
          <mesh filename="package://aist_robotiq/meshes/collision/robotiq_hande-collision.dae" scale="1.0 1.0 1.0"/>
        </geometry>
      </collision>
    </link>
    <link name="${prefix}left_finger">
      <inertial>
        <origin rpy="0 0 0" xyz="0.02262 -0.00759 0.00738"/>
        <mass value="0.03804"/>
        <inertia ixx="13567E-9" ixy="1849E-9" ixz="3622E-9" iyy="15784E-9" iyz="3616E-9" izz="7478E-9"/>
      </inertial>
      <visual>
        <origin rpy="0 0 0" xyz="0 0 0"/>
        <geometry>
          <mesh filename="package://aist_robotiq/meshes/visual/robotiq_hande_finger_1.dae" scale="1.0 1.0 1.0"/>
        </geometry>
        <material name="DarkGray">
          <color rgba=".4 0.4 0.4 1.0"/>
        </material>
      </visual>
      <collision>
        <origin rpy="0 0 0" xyz="0 0 0"/>
        <geometry>
          <mesh filename="package://aist_robotiq/meshes/collision/robotiq_hande_finger_1-collision.dae" scale="1.0 1.0 1.0"/>
        </geometry>
      </collision>
    </link>
    <link name="${prefix}right_finger">
      <inertial>
        <origin rpy="0 0 0" xyz="-0.02262 0.00759 0.00738"/>
        <mass value="0.03804"/>
        <inertia ixx="13567E-9" ixy="1849E-9" ixz="-3622E-9" iyy="15784E-9" iyz="-3616E-9" izz="7478E-9"/>
      </inertial>
      <visual>
        <origin rpy="0 0 0" xyz="0 0 0"/>
        <geometry>
          <mesh filename="package://aist_robotiq/meshes/visual/robotiq_hande_finger_2.dae" scale="1.0 1.0 1.0"/>
        </geometry>
        <material name="DarkGray">
          <color rgba=".4 0.4 0.4 1.0"/>
        </material>
      </visual>
      <collision>
        <origin rpy="0 0 0" xyz="0 0 0"/>
        <geometry>
          <mesh filename="package://aist_robotiq/meshes/collision/robotiq_hande_finger_2-collision.dae" scale="1.0 1.0 1.0"/>
        </geometry>
      </collision>
    </link>

    <gazebo reference="${prefix}hande_link">
      <material>Gazebo/FlatBlack</material>
    </gazebo>
    <gazebo reference="${prefix}right_finger">
      <material>Gazebo/Grey</material>
    </gazebo>
    <gazebo reference="${prefix}left_finger">
      <material>Gazebo/Grey</material>
    </gazebo>
    <joint name="${prefix}finger_joint" type="prismatic">
      <origin rpy="0 0 0" xyz="0 0 0.099"/>
      <parent link="${prefix}hande_link"/>
      <child link="${prefix}left_finger"/>
      <axis xyz="-1 0 0"/>
      <limit effort="130" lower="0" upper="0.025" velocity="0.15"/>
    </joint>
    <joint name="${prefix}right_finger_joint" type="prismatic">
      <origin rpy="0 0 0" xyz="0 0 0.099"/>
      <parent link="${prefix}hande_link"/>
      <child link="${prefix}right_finger"/>
      <axis xyz="1 0 0"/>
      <limit effort="130" lower="0" upper="0.025" velocity="0.15"/>
      <mimic joint="${prefix}finger_joint" multiplier="1" offset="0"/>
    </joint>

    <!-- Improve grasping physics -->
    <gazebo reference="${prefix}left_finger">
      <kp>1000000.0</kp>
      <kd>1.0</kd>
      <mu1>1.0</mu1>
      <mu2>1.0</mu2>
      <minDepth>0.001</minDepth>
    </gazebo>
    <gazebo reference="${prefix}right_finger">
      <kp>1000000.0</kp>
      <kd>1.0</kd>
      <mu1>1.0</mu1>
      <mu2>1.0</mu2>
      <minDepth>0.001</minDepth>
    </gazebo>

    <!-- Mimic joints -->
    <gazebo>
      <plugin filename="libgazebo_mimic_joint_plugin.so"
	      name="${prefix}mimic_robotiq_hande">
        <joint>${prefix}finger_joint</joint>
        <mimicJoint>${prefix}right_finger_joint</mimicJoint>
        <multiplier>1.0</multiplier>
        <offset>0.0</offset>
      </plugin>
    </gazebo>

  </xacro:macro>
</robot>
